Klebert@DESKTOP-BS3T9LA MINGW64 /d/djangoApp/TECSUP-DAE-2021--2 (lab04)
$ cd lab04
(myvenv)
Klebert@DESKTOP-BS3T9LA MINGW64 /d/djangoApp/TECSUP-DAE-2021--2/lab04 (lab04)
$ python manage.py runserver
Watching for file changes with StatReloader

System check identified no issues (0 silenced).

You have 18 unapplied migration(s). Your project may not work properly until you apply the m
Run 'python manage.py migrate' to apply them.
September 08, 2021 - 10:20:27
Django version 3.2.7, using settings 'lab04.settings'
Starting development server at http://127.0.0.1:8000/
Quit the server with CTRL-BREAK.
(myvenv)
Klebert@DESKTOP-BS3T9LA MINGW64 /d/djangoApp/TECSUP-DAE-2021--2/lab04 (lab04)
$ python manage.py startapp recetas
(myvenv)
Klebert@DESKTOP-BS3T9LA MINGW64 /d/djangoApp/TECSUP-DAE-2021--2/lab04 (lab04)
$ python manage.py migrate
Traceback (most recent call last):
  File "manage.py", line 22, in <module>
    main()
  File "manage.py", line 18, in main
    execute_from_command_line(sys.argv)
  File "D:\djangoApp\TECSUP-DAE-2021--2\myvenv\lib\site-packages\django\core\management\__in
    utility.execute()
  File "D:\djangoApp\TECSUP-DAE-2021--2\myvenv\lib\site-packages\django\core\management\__in
    django.setup()
  File "D:\djangoApp\TECSUP-DAE-2021--2\myvenv\lib\site-packages\django\__init__.py", line 2
    apps.populate(settings.INSTALLED_APPS)
  File "D:\djangoApp\TECSUP-DAE-2021--2\myvenv\lib\site-packages\django\apps\registry.py", l
    app_config = AppConfig.create(entry)
  File "D:\djangoApp\TECSUP-DAE-2021--2\myvenv\lib\site-packages\django\apps\config.py", lin
    mod = import_module(mod_path)
  File "C:\Users\Klebert\AppData\Local\Programs\Python\Python37\lib\importlib\__init__.py", 
    return _bootstrap._gcd_import(name[level:], package, level)
  File "<frozen importlib._bootstrap>", line 1006, in _gcd_import
  File "<frozen importlib._bootstrap>", line 983, in _find_and_load
  File "<frozen importlib._bootstrap>", line 965, in _find_and_load_unlocked
ModuleNotFoundError: No module named 'recetas.pps'
(myvenv)
Klebert@DESKTOP-BS3T9LA MINGW64 /d/djangoApp/TECSUP-DAE-2021--2/lab04 (lab04)
$ python manage.py migrate
Traceback (most recent call last):
  File "manage.py", line 22, in <module>
    main()
  File "manage.py", line 18, in main
    execute_from_command_line(sys.argv)
  File "D:\djangoApp\TECSUP-DAE-2021--2\myvenv\lib\site-packages\django\core\management\__in
    utility.execute()
  File "D:\djangoApp\TECSUP-DAE-2021--2\myvenv\lib\site-packages\django\core\management\__in
    django.setup()
  File "D:\djangoApp\TECSUP-DAE-2021--2\myvenv\lib\site-packages\django\__init__.py", line 2
    apps.populate(settings.INSTALLED_APPS)
  File "D:\djangoApp\TECSUP-DAE-2021--2\myvenv\lib\site-packages\django\apps\registry.py", l
    app_config = AppConfig.create(entry)
  File "D:\djangoApp\TECSUP-DAE-2021--2\myvenv\lib\site-packages\django\apps\config.py", lin
    mod = import_module(mod_path)
  File "C:\Users\Klebert\AppData\Local\Programs\Python\Python37\lib\importlib\__init__.py", 
    return _bootstrap._gcd_import(name[level:], package, level)
  File "<frozen importlib._bootstrap>", line 1006, in _gcd_import
  File "<frozen importlib._bootstrap>", line 983, in _find_and_load
  File "<frozen importlib._bootstrap>", line 965, in _find_and_load_unlocked
ModuleNotFoundError: No module named 'recetas.Apps'
(myvenv)
Klebert@DESKTOP-BS3T9LA MINGW64 /d/djangoApp/TECSUP-DAE-2021--2/lab04 (lab04)
$ python manage.py migrate
Operations to perform:
  Apply all migrations: admin, auth, contenttypes, sessions
Running migrations:
  Applying contenttypes.0001_initial... OK
  Applying auth.0001_initial... OK
  Applying admin.0001_initial... OK
  Applying admin.0002_logentry_remove_auto_add... OK
  Applying admin.0003_logentry_add_action_flag_choices... OK
  Applying contenttypes.0002_remove_content_type_name... OK
  Applying auth.0002_alter_permission_name_max_length... OK
  Applying auth.0003_alter_user_email_max_length... OK
  Applying auth.0004_alter_user_username_opts... OK
  Applying auth.0005_alter_user_last_login_null... OK
  Applying auth.0006_require_contenttypes_0002... OK
  Applying auth.0007_alter_validators_add_error_messages... OK
  Applying auth.0008_alter_user_username_max_length... OK
  Applying auth.0009_alter_user_last_name_max_length... OK
  Applying auth.0010_alter_group_name_max_length... OK
  Applying auth.0011_update_proxy_permissions... OK
  Applying auth.0012_alter_user_first_name_max_length... OK
  Applying sessions.0001_initial... OK
(myvenv)
Klebert@DESKTOP-BS3T9LA MINGW64 /d/djangoApp/TECSUP-DAE-2021--2/lab04 (lab04)
$ python manage.py createsuperuser
Username (leave blank to use 'klebert'):
Email address:
Password:
Password (again):
Error: Blank passwords aren't allowed.
Password:
Password (again):
This password is too short. It must contain at least 8 characters.
This password is too common.
This password is entirely numeric.
Bypass password validation and create user anyway? [y/N]: y
Superuser created successfully.
(myvenv)
Klebert@DESKTOP-BS3T9LA MINGW64 /d/djangoApp/TECSUP-DAE-2021--2/lab04 (lab04)
$ python manage.py runserver
Watching for file changes with StatReloader
Performing system checks...

System check identified no issues (0 silenced).
September 08, 2021 - 10:24:54
Django version 3.2.7, using settings 'lab04.settings'
Starting development server at http://127.0.0.1:8000/
Quit the server with CTRL-BREAK.
[08/Sep/2021 10:25:02] "GET / HTTP/1.1" 200 10697
[08/Sep/2021 10:25:02] "GET /static/admin/css/fonts.css HTTP/1.1" 200 423
[08/Sep/2021 10:25:02] "GET /static/admin/fonts/Roboto-Regular-webfont.woff HTTP/1.1" 200 85
[08/Sep/2021 10:25:02] "GET /static/admin/fonts/Roboto-Bold-webfont.woff HTTP/1.1" 200 86184
[08/Sep/2021 10:25:02] "GET /static/admin/fonts/Roboto-Light-webfont.woff HTTP/1.1" 200 8569
Not Found: /favicon.ico
[08/Sep/2021 10:25:03] "GET /favicon.ico HTTP/1.1" 404 2109
[08/Sep/2021 10:25:06] "GET /admin HTTP/1.1" 301 0
[08/Sep/2021 10:25:06] "GET /admin/ HTTP/1.1" 302 0
[08/Sep/2021 10:25:06] "GET /admin/login/?next=/admin/ HTTP/1.1" 200 2214
[08/Sep/2021 10:25:06] "GET /static/admin/css/base.css HTTP/1.1" 200 19513
[08/Sep/2021 10:25:06] "GET /static/admin/css/login.css HTTP/1.1" 200 939
[08/Sep/2021 10:25:06] "GET /static/admin/css/nav_sidebar.css HTTP/1.1" 200 2271
[08/Sep/2021 10:25:06] "GET /static/admin/css/responsive.css HTTP/1.1" 200 18545
[08/Sep/2021 10:25:06] "GET /static/admin/js/nav_sidebar.js HTTP/1.1" 200 1360
[08/Sep/2021 10:25:18] "GET /admin/login/?next=/admin/auth/user HTTP/1.1" 200 2232
[08/Sep/2021 10:25:20] "GET /admin/login/?next=/admin/auth/user HTTP/1.1" 200 2232
[08/Sep/2021 10:25:27] "GET /admin/auth/user HTTP/1.1" 302 0
[08/Sep/2021 10:25:27] "GET /admin/login/?next=/admin/auth/user HTTP/1.1" 200 2232
(myvenv)
Klebert@DESKTOP-BS3T9LA MINGW64 /d/djangoApp/TECSUP-DAE-2021--2/lab04 (lab04)
$ python manage.py createsuperuser
Username: klebert
Error: That username is already taken.
Error: This field cannot be blank.
Username: klebert
Error: That username is already taken.
Username: Manuel
Email address: vixxerror@gmail.com
Password:
Password (again):
This password is too short. It must contain at least 8 characters.
This password is too common.
This password is entirely numeric.
Bypass password validation and create user anyway? [y/N]: y
Superuser created successfully.
(myvenv)
Klebert@DESKTOP-BS3T9LA MINGW64 /d/djangoApp/TECSUP-DAE-2021--2/lab04 (lab04)
$ python manage.py makemigrations
Traceback (most recent call last):
  File "manage.py", line 22, in <module>
    main()
  File "manage.py", line 18, in main
    execute_from_command_line(sys.argv)
  File "D:\djangoApp\TECSUP-DAE-2021--2\myvenv\lib\site-packages\django\core\management\__init__.py", line 419, in execute_from_command_line
    utility.execute()
  File "D:\djangoApp\TECSUP-DAE-2021--2\myvenv\lib\site-packages\django\core\management\__init__.py", line 395, in execute
    django.setup()
  File "D:\djangoApp\TECSUP-DAE-2021--2\myvenv\lib\site-packages\django\__init__.py", line 24, in setup
    apps.populate(settings.INSTALLED_APPS)
  File "D:\djangoApp\TECSUP-DAE-2021--2\myvenv\lib\site-packages\django\apps\registry.py", line 114, in populate
    app_config.import_models()
  File "D:\djangoApp\TECSUP-DAE-2021--2\myvenv\lib\site-packages\django\apps\config.py", line 301, in import_models
    self.models_module = import_module(models_module_name)
  File "C:\Users\Klebert\AppData\Local\Programs\Python\Python37\lib\importlib\__init__.py", line 127, in import_module
    return _bootstrap._gcd_import(name[level:], package, level)
  File "<frozen importlib._bootstrap>", line 1006, in _gcd_import
  File "<frozen importlib._bootstrap>", line 983, in _find_and_load
  File "<frozen importlib._bootstrap>", line 967, in _find_and_load_unlocked
  File "<frozen importlib._bootstrap>", line 677, in _load_unlocked
  File "<frozen importlib._bootstrap_external>", line 728, in exec_module
  File "<frozen importlib._bootstrap>", line 219, in _call_with_frames_removed
  File "D:\djangoApp\TECSUP-DAE-2021--2\lab04\recetas\models.py", line 10, in <module>
    class Receta(models.Model):
  File "D:\djangoApp\TECSUP-DAE-2021--2\lab04\recetas\models.py", line 11, in Receta
    titulo = models.CharField(max_length=100, uniqque=True)
  File "D:\djangoApp\TECSUP-DAE-2021--2\myvenv\lib\site-packages\django\db\models\fields\__i
    super().__init__(*args, **kwargs)
TypeError: __init__() got an unexpected keyword argument 'uniqque'
(myvenv)
Klebert@DESKTOP-BS3T9LA MINGW64 /d/djangoApp/TECSUP-DAE-2021--2/lab04 (lab04)
$ python manage.py makemigrations
Traceback (most recent call last):
  File "manage.py", line 22, in <module>
    main()
  File "manage.py", line 18, in main
    execute_from_command_line(sys.argv)
  File "D:\djangoApp\TECSUP-DAE-2021--2\myvenv\lib\site-packages\django\core\management\__in
    utility.execute()
  File "D:\djangoApp\TECSUP-DAE-2021--2\myvenv\lib\site-packages\django\core\management\__in
    django.setup()
  File "D:\djangoApp\TECSUP-DAE-2021--2\myvenv\lib\site-packages\django\__init__.py", line 2
    apps.populate(settings.INSTALLED_APPS)
  File "D:\djangoApp\TECSUP-DAE-2021--2\myvenv\lib\site-packages\django\apps\registry.py", l
    app_config.import_models()
  File "D:\djangoApp\TECSUP-DAE-2021--2\myvenv\lib\site-packages\django\apps\config.py", lin
    self.models_module = import_module(models_module_name)
  File "C:\Users\Klebert\AppData\Local\Programs\Python\Python37\lib\importlib\__init__.py", 
    return _bootstrap._gcd_import(name[level:], package, level)
  File "<frozen importlib._bootstrap>", line 1006, in _gcd_import
  File "<frozen importlib._bootstrap>", line 983, in _find_and_load
  File "<frozen importlib._bootstrap>", line 967, in _find_and_load_unlocked
  File "<frozen importlib._bootstrap>", line 677, in _load_unlocked
  File "<frozen importlib._bootstrap_external>", line 728, in exec_module
  File "<frozen importlib._bootstrap>", line 219, in _call_with_frames_removed
  File "D:\djangoApp\TECSUP-DAE-2021--2\lab04\recetas\models.py", line 10, in <module>
    class Receta(models.Model):
  File "D:\djangoApp\TECSUP-DAE-2021--2\lab04\recetas\models.py", line 11, in Receta
    titulo = models.CharField(max_length=100, uniqque=True)
  File "D:\djangoApp\TECSUP-DAE-2021--2\myvenv\lib\site-packages\django\db\models\fields\__i
    super().__init__(*args, **kwargs)
TypeError: __init__() got an unexpected keyword argument 'uniqque'
(myvenv)
Klebert@DESKTOP-BS3T9LA MINGW64 /d/djangoApp/TECSUP-DAE-2021--2/lab04 (lab04)
$ , on_delete=models.CASCADE
bash: ,: command not found
(myvenv)
Klebert@DESKTOP-BS3T9LA MINGW64 /d/djangoApp/TECSUP-DAE-2021--2/lab04 (lab04)
$ python manage.py makemigrations
Traceback (most recent call last):
  File "manage.py", line 22, in <module>
    main()
  File "manage.py", line 18, in main
    execute_from_command_line(sys.argv)
  File "D:\djangoApp\TECSUP-DAE-2021--2\myvenv\lib\site-packages\django\core\management\__in
    utility.execute()
  File "D:\djangoApp\TECSUP-DAE-2021--2\myvenv\lib\site-packages\django\core\management\__in
    django.setup()
  File "D:\djangoApp\TECSUP-DAE-2021--2\myvenv\lib\site-packages\django\__init__.py", line 2
    apps.populate(settings.INSTALLED_APPS)
  File "D:\djangoApp\TECSUP-DAE-2021--2\myvenv\lib\site-packages\django\apps\registry.py", l
    app_config.import_models()
  File "D:\djangoApp\TECSUP-DAE-2021--2\myvenv\lib\site-packages\django\apps\config.py", lin
    self.models_module = import_module(models_module_name)
  File "C:\Users\Klebert\AppData\Local\Programs\Python\Python37\lib\importlib\__init__.py", 
    return _bootstrap._gcd_import(name[level:], package, level)
  File "<frozen importlib._bootstrap>", line 1006, in _gcd_import
  File "<frozen importlib._bootstrap>", line 983, in _find_and_load
  File "<frozen importlib._bootstrap>", line 967, in _find_and_load_unlocked
  File "<frozen importlib._bootstrap>", line 677, in _load_unlocked
  File "<frozen importlib._bootstrap_external>", line 728, in exec_module
  File "<frozen importlib._bootstrap>", line 219, in _call_with_frames_removed
  File "D:\djangoApp\TECSUP-DAE-2021--2\lab04\recetas\models.py", line 10, in <module>
    class Receta(models.Model):
  File "D:\djangoApp\TECSUP-DAE-2021--2\myvenv\lib\site-packages\django\db\models\fields\__i
    super().__init__(*args, **kwargs)
TypeError: __init__() got an unexpected keyword argument 'uniqque'
(myvenv)
Klebert@DESKTOP-BS3T9LA MINGW64 /d/djangoApp/TECSUP-DAE-2021--2/lab04 (lab04)
$ python manage.py makemigrations
Migrations for 'recetas':
  recetas\migrations\0001_initial.py
    - Create model Autor
    - Create model Comentario
(myvenv)
Klebert@DESKTOP-BS3T9LA MINGW64 /d/djangoApp/TECSUP-DAE-2021--2/lab04 (lab04)
$ python manage.py migrate
Operations to perform:
  Apply all migrations: admin, auth, contenttypes, recetas, sessions
Running migrations:
  Applying recetas.0001_initial... OK
(myvenv)
Klebert@DESKTOP-BS3T9LA MINGW64 /d/djangoApp/TECSUP-DAE-2021--2/lab04 (lab04)
$ python manage.py shell
Python 3.7.9 (tags/v3.7.9:13c94747c7, Aug 17 2020, 18:58:18) [MSC v.1900 64 bit (AMD64)] on win32                                                                                   n 
Type "help", "copyright", "credits" or "license" for more information.
(InteractiveConsole)
>>> from recetas.models import Autor, Recetas, Comentario
Traceback (most recent call last):
  File "<console>", line 1, in <module>
ImportError: cannot import name 'Recetas' from 'recetas.models' (D:\djangoApp\TECSUP-DAE-2021--2\lab04\recetas\models.py)
>>> from recetas.models import Autor,Receta,Comentario
>>> a = Autor(nombre='Javier Perez',email='eperez@gmail.com')
>>> a.save()
>>> Autor.objects.all()
<QuerySet [<Autor: Javier Perez>]>
>>> primer = Autor.objects.get(pk=1) 
>>> r1 = Receta.objects.create(
... titulo='Huevo frito' 
... ingredientes='huevo,sal,aceite' 
  File "<console>", line 3
    ingredientes='huevo,sal,aceite'
               ^
SyntaxError: invalid syntax
>>> ,
  File "<console>", line 1
    ,
    ^
SyntaxError: invalid syntax
>>> ,ingredientes='huevo,sal,aceite',
  File "<console>", line 1
    ,ingredientes='huevo,sal,aceite',
    ^
SyntaxError: invalid syntax
>>> ingredientes='huevo,sal,aceite',
>>> preparacion='Calentar la sarten y bla bla bla',
>>> autor=primer)
  File "<console>", line 1
    autor=primer)
                ^
SyntaxError: invalid syntax
>>> autor=primer)
  File "<console>", line 1
    autor=primer)
                ^
SyntaxError: invalid syntax
>>>       
>>> 
>>> as
  File "<console>", line 1
    as
     ^
SyntaxError: invalid syntax
>>> exit
Use exit() or Ctrl-Z plus Return to exit
>>> r1=Receta.objects.create(
... titulo='huevo frito',
... ingredientes='huevo,sal,aceite',
... preparacion='Calentar la sarten y bla bla bla'
... autor=primer)
  File "<console>", line 5
    autor=primer)
        ^
SyntaxError: invalid syntax
>>> r1=Receta.objects.create(
... titulo='huevo frito',
... ingredientes='huevo,sal,aceite',
... preparacion='Calentar la sarten y bla bla bla',
... autor=primer)
Traceback (most recent call last):
  File "<console>", line 5, in <module>
  File "D:\djangoApp\TECSUP-DAE-2021--2\myvenv\lib\site-packages\django\db\models\manager.py", line 85, in manager_method
    return getattr(self.get_queryset(), name)(*args, **kwargs)
  File "D:\djangoApp\TECSUP-DAE-2021--2\myvenv\lib\site-packages\django\db\models\query.py", line 451, in create    
    obj = self.model(**kwargs)
  File "D:\djangoApp\TECSUP-DAE-2021--2\myvenv\lib\site-packages\django\db\models\base.py", line 503, in __init__   
    raise TypeError("%s() got an unexpected keyword argument '%s'" % (cls.__name__, kwarg))
TypeError: Receta() got an unexpected keyword argument 'preparacion'
>>> r1=Receta.objects.create(
... titulo='huevo frito',
... ingredientes='huevo,sal,aceite',
... preparacion='Calentar la sarten y bla bla bla',
... autor=primer)
Traceback (most recent call last):
  File "<console>", line 5, in <module>
  File "D:\djangoApp\TECSUP-DAE-2021--2\myvenv\lib\site-packages\django\db\models\manager.py", line 85, in manager_method
    return getattr(self.get_queryset(), name)(*args, **kwargs)
  File "D:\djangoApp\TECSUP-DAE-2021--2\myvenv\lib\site-packages\django\db\models\query.py", line 451, in create    
    obj = self.model(**kwargs)
  File "D:\djangoApp\TECSUP-DAE-2021--2\myvenv\lib\site-packages\django\db\models\base.py", line 503, in __init__   
    raise TypeError("%s() got an unexpected keyword argument '%s'" % (cls.__name__, kwarg))
TypeError: Receta() got an unexpected keyword argument 'preparacion'
>>> Receta.objects.all()
<QuerySet []>
>>> segundo = Autor.objects.get(pk=2) 
Traceback (most recent call last):
  File "<console>", line 1, in <module>
  File "D:\djangoApp\TECSUP-DAE-2021--2\myvenv\lib\site-packages\django\db\models\manager.py", line 85, in manager_method
    return getattr(self.get_queryset(), name)(*args, **kwargs)
  File "D:\djangoApp\TECSUP-DAE-2021--2\myvenv\lib\site-packages\django\db\models\query.py", line 437, in get
    self.model._meta.object_name
recetas.models.Autor.DoesNotExist: Autor matching query does not exist.
>>> Primer=Autor.objects.get(pk=1)
>>> r2=Receta.objects.create(
... titulo='Huevo frito',
... ingredientes='huevo,sal,aceite',
... preparacion='Calentar la sarten y bla bla bla',
Traceback (most recent call last):
  File "<console>", line 5, in <module>
  File "D:\djangoApp\TECSUP-DAE-2021--2\myvenv\lib\site-packages\django\db\models\manager.py", line 85, in manager_method
    return getattr(self.get_queryset(), name)(*args, **kwargs)
  File "D:\djangoApp\TECSUP-DAE-2021--2\myvenv\lib\site-packages\django\db\models\query.py", line 451, in create
    obj = self.model(**kwargs)
  File "D:\djangoApp\TECSUP-DAE-2021--2\myvenv\lib\site-packages\django\db\models\base.py", line 503, in __init__
    raise TypeError("%s() got an unexpected keyword argument '%s'" % (cls.__name__, kwarg))
TypeError: Receta() got an unexpected keyword argument 'preparacion'
>>> r2=Receta.objects.create(
... titulo='Huevo frito',
... ingredientes='huevo,sal,aceite',
... preaparacion='Calentar la sarten y bla bla bla',
... autor=Primer)
>>> Receta.objects.all()
<QuerySet [<Receta: Huevo frito>]>
>>> c1 = Cometnario.objects.create(
... receta=r2,
... texto='Un clasico para el desayuno')
Traceback (most recent call last):
  File "<console>", line 1, in <module>
NameError: name 'Cometnario' is not defined
>>> c1 = Comentario.objects.create(
... receta=r2,
... texto='Un clasico para el desayuno')
>>> Cometnario.objects.all()
Traceback (most recent call last):
  File "<console>", line 1, in <module>
NameError: name 'Cometnario' is not defined
>>> Cometnario.objects.all()
Traceback (most recent call last):
  File "<console>", line 1, in <module>
NameError: name 'Cometnario' is not defined
>>> Comentario.objects.all()
<QuerySet [<Comentario: Un clasico para el desayuno>]>
>>> re=Receta.objects.create(
... titulo='agua Hervida',
... ingredientes='agua',
... preparacion='Poner la tetera en el bla bla bla',
... autor=Primer)
  File "<console>", line 5, in <module>
  File "D:\djangoApp\TECSUP-DAE-2021--2\myvenv\lib\site-packages\django\db\models\manager.py", line 85, in manager_methodethod
    return getattr(self.get_queryset(), name)(*args, **kwargs)
  File "D:\djangoApp\TECSUP-DAE-2021--2\myvenv\lib\site-packages\django\db\models\query.py", line 451, in create    
    obj = self.model(**kwargs)
  File "D:\djangoApp\TECSUP-DAE-2021--2\myvenv\lib\site-packages\django\db\models\base.py", line 503, in __init__   
    raise TypeError("%s() got an unexpected keyword argument '%s'" % (cls.__name__, kwarg))
TypeError: Receta() got an unexpected keyword argument 'preparacion'
>>> re=Receta.objects.create(
... titulo='agua Hervida',
... preaparacion='Poner la tetera en el bla bla bla',
... autor=Primer)
>>> Receta.objects.all()
<QuerySet [<Receta: Huevo frito>, <Receta: agua Hervida>]>
>>> Receta.objects.exclude(ingredientes_startswith='A') 
Traceback (most recent call last):
  File "<console>", line 1, in <module>
  File "D:\djangoApp\TECSUP-DAE-2021--2\myvenv\lib\site-packages\django\db\models\manager.py", line 85, in manager_method
    return getattr(self.get_queryset(), name)(*args, **kwargs)
  File "D:\djangoApp\TECSUP-DAE-2021--2\myvenv\lib\site-packages\django\db\models\query.py", line 949, in exclude   
    return self._filter_or_exclude(True, args, kwargs)
  File "D:\djangoApp\TECSUP-DAE-2021--2\myvenv\lib\site-packages\django\db\models\query.py", line 961, in _filter_or_exclude
    clone._filter_or_exclude_inplace(negate, args, kwargs)
  File "D:\djangoApp\TECSUP-DAE-2021--2\myvenv\lib\site-packages\django\db\models\query.py", line 966, in _filter_or_exclude_inplace
    self._query.add_q(~Q(*args, **kwargs))
  File "D:\djangoApp\TECSUP-DAE-2021--2\myvenv\lib\site-packages\django\db\models\sql\query.py", line 1393, in add_q
    clause, _ = self._add_q(q_object, self.used_aliases)
  File "D:\djangoApp\TECSUP-DAE-2021--2\myvenv\lib\site-packages\django\db\models\sql\query.py", line 1415, in _add_q
    split_subq=split_subq, check_filterable=check_filterable,
  File "D:\djangoApp\TECSUP-DAE-2021--2\myvenv\lib\site-packages\django\db\models\sql\query.py", line 1286, in build_filter
    lookups, parts, reffed_expression = self.solve_lookup_type(arg)
  File "D:\djangoApp\TECSUP-DAE-2021--2\myvenv\lib\site-packages\django\db\models\sql\query.py", line 1112, in solve_lookup_type
    _, field, _, lookup_parts = self.names_to_path(lookup_splitted, self.get_meta())
  File "D:\djangoApp\TECSUP-DAE-2021--2\myvenv\lib\site-packages\django\db\models\sql\query.py", line 1540, in names_to_path
    "Choices are: %s" % (name, ", ".join(available)))
django.core.exceptions.FieldError: Cannot resolve keyword 'ingredientes_startswith' into field. Choices are: autor, 
autor_id, comentario, id, ingredientes, preaparacion, tiempo_registro, titulo
>>> Receta.objects.exclude(ingredientes__startswith='A')  
<QuerySet [<Receta: Huevo frito>, <Receta: agua Hervida>]>
>>> Receta.objects.filter(preparacion__contains='tetera')
Traceback (most recent call last):
  File "<console>", line 1, in <module>
  File "D:\djangoApp\TECSUP-DAE-2021--2\myvenv\lib\site-packages\django\db\models\manager.py", line 85, in manager_method
    return getattr(self.get_queryset(), name)(*args, **kwargs)
  File "D:\djangoApp\TECSUP-DAE-2021--2\myvenv\lib\site-packages\django\db\models\query.py", line 941, in filter    
    return self._filter_or_exclude(False, args, kwargs)
  File "D:\djangoApp\TECSUP-DAE-2021--2\myvenv\lib\site-packages\django\db\models\query.py", line 961, in _filter_or_exclude
    clone._filter_or_exclude_inplace(negate, args, kwargs)
  File "D:\djangoApp\TECSUP-DAE-2021--2\myvenv\lib\site-packages\django\db\models\query.py", line 968, in _filter_or_exclude_inplace
    self._query.add_q(Q(*args, **kwargs))
  File "D:\djangoApp\TECSUP-DAE-2021--2\myvenv\lib\site-packages\django\db\models\sql\query.py", line 1393, in add_q
    clause, _ = self._add_q(q_object, self.used_aliases)
  File "D:\djangoApp\TECSUP-DAE-2021--2\myvenv\lib\site-packages\django\db\models\sql\query.py", line 1415, in _add_q
    split_subq=split_subq, check_filterable=check_filterable,
  File "D:\djangoApp\TECSUP-DAE-2021--2\myvenv\lib\site-packages\django\db\models\sql\query.py", line 1286, in build_filter
    lookups, parts, reffed_expression = self.solve_lookup_type(arg)
  File "D:\djangoApp\TECSUP-DAE-2021--2\myvenv\lib\site-packages\django\db\models\sql\query.py", line 1112, in solve_lookup_type
    _, field, _, lookup_parts = self.names_to_path(lookup_splitted, self.get_meta())
  File "D:\djangoApp\TECSUP-DAE-2021--2\myvenv\lib\site-packages\django\db\models\sql\query.py", line 1540, in names_to_path
    "Choices are: %s" % (name, ", ".join(available)))
django.core.exceptions.FieldError: Cannot resolve keyword 'preparacion' into field. Choices are: autor, autor_id, comentario, id, ingredientes, preaparacion, tiempo_registro, titulo
>>> Receta.objects.filter(preaparacion__contains='tetera') 
<QuerySet [<Receta: agua Hervida>]>
>>> Receta.objects.all().order_by('titulo')              
<QuerySet [<Receta: Huevo frito>, <Receta: agua Hervida>]>
>>> Receta.objects.all().order_by('titulo').reverse()
<QuerySet [<Receta: agua Hervida>, <Receta: Huevo frito>]>
>>> Cometnario.objects.filter(receta=r2) 
Traceback (most recent call last):
  File "<console>", line 1, in <module>
NameError: name 'Cometnario' is not defined
>>> Comentario.objects.filter(receta=r2) 
<QuerySet [<Comentario: Un clasico para el desayuno>]>
>>> Comentario.objects.filter(receta=re) 
<QuerySet []>
>>> Receta.objects.filter(titulo='Huevo frito').update(titulo='Huevo frito')
1
>>> Receta.objects.all()
<QuerySet [<Receta: Huevo frito>, <Receta: agua Hervida>]>
>>> c2 = Comentario.objects.create(
... receta=r2,
... texto='Para pasar el hambre'
... )
>>> Comentario.objects.filter(receta=r2).count()
2
>>> Comentario.objects.filter(receta=re).count()
0
>>> c3 = Comentario.objects.create(
... receta=re,
... texto='Receta sin sentido')
>>> Comentario.objects.filter(receta=r2)
<QuerySet [<Comentario: Un clasico para el desayuno>, <Comentario: Para pasar el hambre>]>
>>> c3.delete()
(1, {'recetas.Comentario': 1})
>>> Comentario.objects.filter(receta=r2)
<QuerySet [<Comentario: Un clasico para el desayuno>, <Comentario: Para pasar el hambre>]>
>>> Receta.objects.get(titulo='Agua Hervida').autor.nombre
Traceback (most recent call last):
  File "<console>", line 1, in <module>
  File "D:\djangoApp\TECSUP-DAE-2021--2\myvenv\lib\site-packages\django\db\models\manager.py", line 85, in manager_method
    return getattr(self.get_queryset(), name)(*args, **kwargs)
  File "D:\djangoApp\TECSUP-DAE-2021--2\myvenv\lib\site-packages\django\db\models\query.py", line 437, in get       
    self.model._meta.object_name
recetas.models.Receta.DoesNotExist: Receta matching query does not exist.
>>> Receta.objects.get(titulo='agua Hervida').autor.nombre 
'Javier Perez'
>>>  Receta.objects.get(titulo='agua Hervida').autor.email 
  File "<console>", line 1
    Receta.objects.get(titulo='agua Hervida').autor.email
    ^
IndentationError: unexpected indent
>>> Receta.objects.get(titulo='agua Hervida').autor.nombre 
'Javier Perez'
>>>